[2023-03-22T00:06:13.711+0000] {taskinstance.py:1083} INFO - Dependencies all met for <TaskInstance: s3_dag.upload_to_s3 manual__2023-03-22T00:06:09.552160+00:00 [queued]>
[2023-03-22T00:06:13.745+0000] {taskinstance.py:1083} INFO - Dependencies all met for <TaskInstance: s3_dag.upload_to_s3 manual__2023-03-22T00:06:09.552160+00:00 [queued]>
[2023-03-22T00:06:13.746+0000] {taskinstance.py:1279} INFO - 
--------------------------------------------------------------------------------
[2023-03-22T00:06:13.746+0000] {taskinstance.py:1280} INFO - Starting attempt 1 of 1
[2023-03-22T00:06:13.747+0000] {taskinstance.py:1281} INFO - 
--------------------------------------------------------------------------------
[2023-03-22T00:06:13.804+0000] {taskinstance.py:1300} INFO - Executing <Task(PythonOperator): upload_to_s3> on 2023-03-22 00:06:09.552160+00:00
[2023-03-22T00:06:13.815+0000] {standard_task_runner.py:55} INFO - Started process 16004 to run task
[2023-03-22T00:06:13.825+0000] {standard_task_runner.py:82} INFO - Running: ['***', 'tasks', 'run', 's3_dag', 'upload_to_s3', 'manual__2023-03-22T00:06:09.552160+00:00', '--job-id', '6', '--raw', '--subdir', 'DAGS_FOLDER/adhoc_dag.py', '--cfg-path', '/tmp/tmpwpcguvo5']
[2023-03-22T00:06:13.827+0000] {standard_task_runner.py:83} INFO - Job 6: Subtask upload_to_s3
[2023-03-22T00:06:14.029+0000] {task_command.py:388} INFO - Running <TaskInstance: s3_dag.upload_to_s3 manual__2023-03-22T00:06:09.552160+00:00 [running]> on host cc4c8b38f579
[2023-03-22T00:06:14.241+0000] {taskinstance.py:1509} INFO - Exporting the following env vars:
AIRFLOW_CTX_DAG_OWNER=***
AIRFLOW_CTX_DAG_ID=s3_dag
AIRFLOW_CTX_TASK_ID=upload_to_s3
AIRFLOW_CTX_EXECUTION_DATE=2023-03-22T00:06:09.552160+00:00
AIRFLOW_CTX_TRY_NUMBER=1
AIRFLOW_CTX_DAG_RUN_ID=manual__2023-03-22T00:06:09.552160+00:00
[2023-03-22T00:06:14.270+0000] {base.py:73} INFO - Using connection ID 's3_conn' for task execution.
[2023-03-22T00:06:14.271+0000] {connection_wrapper.py:334} INFO - AWS Connection (conn_id='s3_conn', conn_type='aws') credentials retrieved from login and password.
[2023-03-22T00:06:16.742+0000] {taskinstance.py:1768} ERROR - Task failed with exception
Traceback (most recent call last):
  File "/home/airflow/.local/lib/python3.7/site-packages/airflow/operators/python.py", line 175, in execute
    return_value = self.execute_callable()
  File "/home/airflow/.local/lib/python3.7/site-packages/airflow/operators/python.py", line 192, in execute_callable
    return self.python_callable(*self.op_args, **self.op_kwargs)
  File "/opt/airflow/dags/adhoc_dag.py", line 9, in upload_to_s3
    hook.load_file(filename=filename, key=key, bucket_name=bucket_name)
  File "/home/airflow/.local/lib/python3.7/site-packages/airflow/providers/amazon/aws/hooks/s3.py", line 99, in wrapper
    return func(*bound_args.args, **bound_args.kwargs)
  File "/home/airflow/.local/lib/python3.7/site-packages/airflow/providers/amazon/aws/hooks/s3.py", line 70, in wrapper
    return func(*bound_args.args, **bound_args.kwargs)
  File "/home/airflow/.local/lib/python3.7/site-packages/airflow/providers/amazon/aws/hooks/s3.py", line 646, in load_file
    client.upload_file(filename, bucket_name, key, ExtraArgs=extra_args, Config=self.transfer_config)
  File "/home/airflow/.local/lib/python3.7/site-packages/boto3/s3/inject.py", line 148, in upload_file
    callback=Callback,
  File "/home/airflow/.local/lib/python3.7/site-packages/boto3/s3/transfer.py", line 292, in upload_file
    future.result()
  File "/home/airflow/.local/lib/python3.7/site-packages/s3transfer/futures.py", line 103, in result
    return self._coordinator.result()
  File "/home/airflow/.local/lib/python3.7/site-packages/s3transfer/futures.py", line 266, in result
    raise self._exception
  File "/home/airflow/.local/lib/python3.7/site-packages/s3transfer/tasks.py", line 269, in _main
    self._submit(transfer_future=transfer_future, **kwargs)
  File "/home/airflow/.local/lib/python3.7/site-packages/s3transfer/upload.py", line 585, in _submit
    upload_input_manager.provide_transfer_size(transfer_future)
  File "/home/airflow/.local/lib/python3.7/site-packages/s3transfer/upload.py", line 244, in provide_transfer_size
    self._osutil.get_file_size(transfer_future.meta.call_args.fileobj)
  File "/home/airflow/.local/lib/python3.7/site-packages/s3transfer/utils.py", line 247, in get_file_size
    return os.path.getsize(filename)
  File "/usr/local/lib/python3.7/genericpath.py", line 50, in getsize
    return os.stat(filename).st_size
FileNotFoundError: [Errno 2] No such file or directory: '/home/jvidelefsky/airflow_a4/JV_AUDIO_EXAMPLE.WAV'
[2023-03-22T00:06:16.769+0000] {taskinstance.py:1323} INFO - Marking task as FAILED. dag_id=s3_dag, task_id=upload_to_s3, execution_date=20230322T000609, start_date=20230322T000613, end_date=20230322T000616
[2023-03-22T00:06:16.811+0000] {standard_task_runner.py:105} ERROR - Failed to execute job 6 for task upload_to_s3 ([Errno 2] No such file or directory: '/home/jvidelefsky/airflow_a4/JV_AUDIO_EXAMPLE.WAV'; 16004)
[2023-03-22T00:06:16.856+0000] {local_task_job.py:208} INFO - Task exited with return code 1
[2023-03-22T00:06:16.907+0000] {taskinstance.py:2578} INFO - 0 downstream tasks scheduled from follow-on schedule check
