[2023-03-22T01:54:39.730+0000] {taskinstance.py:1083} INFO - Dependencies all met for <TaskInstance: s3_dag.upload_to_s3 manual__2023-03-22T01:54:32.694905+00:00 [queued]>
[2023-03-22T01:54:39.761+0000] {taskinstance.py:1083} INFO - Dependencies all met for <TaskInstance: s3_dag.upload_to_s3 manual__2023-03-22T01:54:32.694905+00:00 [queued]>
[2023-03-22T01:54:39.761+0000] {taskinstance.py:1279} INFO - 
--------------------------------------------------------------------------------
[2023-03-22T01:54:39.761+0000] {taskinstance.py:1280} INFO - Starting attempt 1 of 1
[2023-03-22T01:54:39.762+0000] {taskinstance.py:1281} INFO - 
--------------------------------------------------------------------------------
[2023-03-22T01:54:39.807+0000] {taskinstance.py:1300} INFO - Executing <Task(PythonOperator): upload_to_s3> on 2023-03-22 01:54:32.694905+00:00
[2023-03-22T01:54:39.818+0000] {standard_task_runner.py:55} INFO - Started process 25535 to run task
[2023-03-22T01:54:39.826+0000] {standard_task_runner.py:82} INFO - Running: ['***', 'tasks', 'run', 's3_dag', 'upload_to_s3', 'manual__2023-03-22T01:54:32.694905+00:00', '--job-id', '10', '--raw', '--subdir', 'DAGS_FOLDER/adhoc_dag.py', '--cfg-path', '/tmp/tmp6p7g2my9']
[2023-03-22T01:54:39.828+0000] {standard_task_runner.py:83} INFO - Job 10: Subtask upload_to_s3
[2023-03-22T01:54:39.987+0000] {task_command.py:388} INFO - Running <TaskInstance: s3_dag.upload_to_s3 manual__2023-03-22T01:54:32.694905+00:00 [running]> on host cc4c8b38f579
[2023-03-22T01:54:40.195+0000] {taskinstance.py:1509} INFO - Exporting the following env vars:
AIRFLOW_CTX_DAG_OWNER=***
AIRFLOW_CTX_DAG_ID=s3_dag
AIRFLOW_CTX_TASK_ID=upload_to_s3
AIRFLOW_CTX_EXECUTION_DATE=2023-03-22T01:54:32.694905+00:00
AIRFLOW_CTX_TRY_NUMBER=1
AIRFLOW_CTX_DAG_RUN_ID=manual__2023-03-22T01:54:32.694905+00:00
[2023-03-22T01:54:40.228+0000] {base.py:73} INFO - Using connection ID 's3_conn' for task execution.
[2023-03-22T01:54:40.230+0000] {connection_wrapper.py:334} INFO - AWS Connection (conn_id='s3_conn', conn_type='aws') credentials retrieved from login and password.
[2023-03-22T01:54:43.039+0000] {taskinstance.py:1768} ERROR - Task failed with exception
Traceback (most recent call last):
  File "/home/airflow/.local/lib/python3.7/site-packages/airflow/operators/python.py", line 175, in execute
    return_value = self.execute_callable()
  File "/home/airflow/.local/lib/python3.7/site-packages/airflow/operators/python.py", line 192, in execute_callable
    return self.python_callable(*self.op_args, **self.op_kwargs)
  File "/opt/airflow/dags/adhoc_dag.py", line 19, in upload_to_s3
    hook.load_file(filename=filename, key=key, bucket_name=bucket_name)
  File "/home/airflow/.local/lib/python3.7/site-packages/airflow/providers/amazon/aws/hooks/s3.py", line 99, in wrapper
    return func(*bound_args.args, **bound_args.kwargs)
  File "/home/airflow/.local/lib/python3.7/site-packages/airflow/providers/amazon/aws/hooks/s3.py", line 70, in wrapper
    return func(*bound_args.args, **bound_args.kwargs)
  File "/home/airflow/.local/lib/python3.7/site-packages/airflow/providers/amazon/aws/hooks/s3.py", line 631, in load_file
    raise ValueError(f"The key {key} already exists.")
ValueError: The key Uploaded_Audio_Files/JV_AUDIO_EXAMPLE.WAV already exists.
[2023-03-22T01:54:43.049+0000] {taskinstance.py:1323} INFO - Marking task as FAILED. dag_id=s3_dag, task_id=upload_to_s3, execution_date=20230322T015432, start_date=20230322T015439, end_date=20230322T015443
[2023-03-22T01:54:43.067+0000] {standard_task_runner.py:105} ERROR - Failed to execute job 10 for task upload_to_s3 (The key Uploaded_Audio_Files/JV_AUDIO_EXAMPLE.WAV already exists.; 25535)
[2023-03-22T01:54:43.097+0000] {local_task_job.py:208} INFO - Task exited with return code 1
[2023-03-22T01:54:43.117+0000] {taskinstance.py:2578} INFO - 0 downstream tasks scheduled from follow-on schedule check
