[2023-03-21T23:51:23.950+0000] {taskinstance.py:1083} INFO - Dependencies all met for <TaskInstance: s3_dag.upload_to_s3 scheduled__2023-03-20T00:00:00+00:00 [queued]>
[2023-03-21T23:51:23.984+0000] {taskinstance.py:1083} INFO - Dependencies all met for <TaskInstance: s3_dag.upload_to_s3 scheduled__2023-03-20T00:00:00+00:00 [queued]>
[2023-03-21T23:51:23.985+0000] {taskinstance.py:1279} INFO - 
--------------------------------------------------------------------------------
[2023-03-21T23:51:23.986+0000] {taskinstance.py:1280} INFO - Starting attempt 1 of 1
[2023-03-21T23:51:23.986+0000] {taskinstance.py:1281} INFO - 
--------------------------------------------------------------------------------
[2023-03-21T23:51:24.041+0000] {taskinstance.py:1300} INFO - Executing <Task(PythonOperator): upload_to_s3> on 2023-03-20 00:00:00+00:00
[2023-03-21T23:51:24.060+0000] {standard_task_runner.py:55} INFO - Started process 14664 to run task
[2023-03-21T23:51:24.070+0000] {standard_task_runner.py:82} INFO - Running: ['***', 'tasks', 'run', 's3_dag', 'upload_to_s3', 'scheduled__2023-03-20T00:00:00+00:00', '--job-id', '4', '--raw', '--subdir', 'DAGS_FOLDER/adhoc_dag.py', '--cfg-path', '/tmp/tmp7w838l_5']
[2023-03-21T23:51:24.072+0000] {standard_task_runner.py:83} INFO - Job 4: Subtask upload_to_s3
[2023-03-21T23:51:24.265+0000] {task_command.py:388} INFO - Running <TaskInstance: s3_dag.upload_to_s3 scheduled__2023-03-20T00:00:00+00:00 [running]> on host cc4c8b38f579
[2023-03-21T23:51:24.571+0000] {taskinstance.py:1509} INFO - Exporting the following env vars:
AIRFLOW_CTX_DAG_OWNER=***
AIRFLOW_CTX_DAG_ID=s3_dag
AIRFLOW_CTX_TASK_ID=upload_to_s3
AIRFLOW_CTX_EXECUTION_DATE=2023-03-20T00:00:00+00:00
AIRFLOW_CTX_TRY_NUMBER=1
AIRFLOW_CTX_DAG_RUN_ID=scheduled__2023-03-20T00:00:00+00:00
[2023-03-21T23:51:24.626+0000] {base.py:73} INFO - Using connection ID 's3_conn' for task execution.
[2023-03-21T23:51:24.628+0000] {connection_wrapper.py:334} INFO - AWS Connection (conn_id='s3_conn', conn_type='aws') credentials retrieved from login and password.
[2023-03-21T23:51:31.469+0000] {taskinstance.py:1768} ERROR - Task failed with exception
Traceback (most recent call last):
  File "/home/airflow/.local/lib/python3.7/site-packages/airflow/operators/python.py", line 175, in execute
    return_value = self.execute_callable()
  File "/home/airflow/.local/lib/python3.7/site-packages/airflow/operators/python.py", line 192, in execute_callable
    return self.python_callable(*self.op_args, **self.op_kwargs)
  File "/opt/airflow/dags/adhoc_dag.py", line 9, in upload_to_s3
    hook.load_file(filename=filename, key=key, bucket_name=bucket_name)
  File "/home/airflow/.local/lib/python3.7/site-packages/airflow/providers/amazon/aws/hooks/s3.py", line 99, in wrapper
    return func(*bound_args.args, **bound_args.kwargs)
  File "/home/airflow/.local/lib/python3.7/site-packages/airflow/providers/amazon/aws/hooks/s3.py", line 70, in wrapper
    return func(*bound_args.args, **bound_args.kwargs)
  File "/home/airflow/.local/lib/python3.7/site-packages/airflow/providers/amazon/aws/hooks/s3.py", line 630, in load_file
    if not replace and self.check_for_key(key, bucket_name):
  File "/home/airflow/.local/lib/python3.7/site-packages/airflow/providers/amazon/aws/hooks/s3.py", line 99, in wrapper
    return func(*bound_args.args, **bound_args.kwargs)
  File "/home/airflow/.local/lib/python3.7/site-packages/airflow/providers/amazon/aws/hooks/s3.py", line 70, in wrapper
    return func(*bound_args.args, **bound_args.kwargs)
  File "/home/airflow/.local/lib/python3.7/site-packages/airflow/providers/amazon/aws/hooks/s3.py", line 481, in check_for_key
    obj = self.head_object(key, bucket_name)
  File "/home/airflow/.local/lib/python3.7/site-packages/airflow/providers/amazon/aws/hooks/s3.py", line 99, in wrapper
    return func(*bound_args.args, **bound_args.kwargs)
  File "/home/airflow/.local/lib/python3.7/site-packages/airflow/providers/amazon/aws/hooks/s3.py", line 70, in wrapper
    return func(*bound_args.args, **bound_args.kwargs)
  File "/home/airflow/.local/lib/python3.7/site-packages/airflow/providers/amazon/aws/hooks/s3.py", line 469, in head_object
    raise e
  File "/home/airflow/.local/lib/python3.7/site-packages/airflow/providers/amazon/aws/hooks/s3.py", line 464, in head_object
    return self.get_conn().head_object(Bucket=bucket_name, Key=key)
  File "/home/airflow/.local/lib/python3.7/site-packages/botocore/client.py", line 530, in _api_call
    return self._make_api_call(operation_name, kwargs)
  File "/home/airflow/.local/lib/python3.7/site-packages/botocore/client.py", line 960, in _make_api_call
    raise error_class(parsed_response, operation_name)
botocore.exceptions.ClientError: An error occurred (403) when calling the HeadObject operation: Forbidden
[2023-03-21T23:51:31.710+0000] {taskinstance.py:1323} INFO - Marking task as FAILED. dag_id=s3_dag, task_id=upload_to_s3, execution_date=20230320T000000, start_date=20230321T235123, end_date=20230321T235131
[2023-03-21T23:51:31.920+0000] {standard_task_runner.py:105} ERROR - Failed to execute job 4 for task upload_to_s3 (An error occurred (403) when calling the HeadObject operation: Forbidden; 14664)
[2023-03-21T23:51:32.072+0000] {local_task_job.py:208} INFO - Task exited with return code 1
[2023-03-21T23:51:32.367+0000] {taskinstance.py:2578} INFO - 0 downstream tasks scheduled from follow-on schedule check
